<?xml version="1.0"?>

<robot name="adam">
    <link name="base_link">
        <inertial>
            <origin xyz="-0.074 0.0 -0.19" rpy="0 0 -1.57"/>
            <mass value="60"/>
            <inertia ixx="2.529" ixy="-0.004768" ixz="-0.8146" iyy="4.984" iyx="-0.004768" iyz="-0.02831" izz="4.385" izx="-0.8146" izy="-0.02831"/>
        </inertial>

        <collision>
            <origin xyz="0.1465 0 -0.082" rpy="0 0 0"/>
            <geometry>
                <box size="1.02 0.43 0.31" />
            </geometry>
        </collision>

        <visual>
            <origin xyz="0.1465 0 -0.082" rpy="0 0 0"/>
            <geometry>
                <box size="1.02 0.43 0.31" />
            </geometry>
        </visual>
    </link>

    <link name="left_wheel_back">
        <inertial>
            <origin rpy="0 0 0" xyz="0 0 0"/>
            <mass value="4.0"/>
            <inertia ixx="0.08847" ixy="0" ixz="0" iyy="0.1693" iyx="0" iyz="0" izz="0.08847" izx="0" izy="0"/>
        </inertial>

        <collision>
            <origin xyz="0 0 0" rpy="1.57 0 0"/>
            <geometry>
                <cylinder length="0.095" radius="0.19"/>
            </geometry>
        </collision>

        <visual>
            <origin xyz="0 0 0" rpy="1.57 0 0"/>
            <geometry>
                <cylinder length="0.095" radius="0.19"/>
            </geometry>
        </visual>
    </link>

    <link name="right_wheel_back">
        <inertial>
            <origin rpy="0 0 0" xyz="0 0 0"/>
            <mass value="4.0"/>
            <inertia ixx="0.08847" ixy="0" ixz="0" iyy="0.1693" iyx="0" iyz="0" izz="0.08847" izx="0" izy="0"/>
        </inertial>

        <collision>
            <origin xyz="0 0 0" rpy="1.57 0 0"/>
            <geometry>
                <cylinder length="0.095" radius="0.19"/>
            </geometry>
        </collision>

        <visual>
            <origin xyz="0 0 0" rpy="1.57 0 0"/>
            <geometry>
                <cylinder length="0.095" radius="0.19"/>
            </geometry>
        </visual>
    </link>

    <joint name="base_link_to_left_wheel_back" type="continuous">
        <parent link="base_link" />
        <child link="left_wheel_back" />
        <origin xyz="-0.125 0.309 -0.1425"/>
        <axis xyz="0 1 0"/>
    </joint>

    <joint name="base_link_to_right_wheel_back" type="continuous">
        <parent link="base_link" />
        <child link="right_wheel_back" />
        <origin xyz="-0.125 -0.309 -0.1425"/>
        <axis xyz="0 1 0"/>
    </joint>

    <link name="front_wheel_conn">
        <inertial>
            <origin xyz="0.0 0 0" rpy="0 0 0"/>
            <mass value="0.100"/>
            <inertia ixx="0.0001785" ixy="0" ixz="0" iyy="0.0001757" iyx="0" iyz="0" izz="0.00007551" izx="0" izy="0"/>
        </inertial>

        <visual>
            <origin xyz="0 0 0" rpy="0 0 0"/>
            <geometry>
                <box size="0.0499 0.044 0.05215"/>
            </geometry>
        </visual>

        <collision>
            <origin xyz="0 0 0" rpy="0 0 0"/>
            <geometry>
                <box size="0.0499 0.044 0.05215"/>
            </geometry>
        </collision>
    </link>

    <joint name="wheel_front_conn" type="continuous">
        <parent link="base_link"/>
        <child link="front_wheel_conn"/>
        <origin xyz="0.4616 0.0 -0.28815"/>
        <axis xyz="0 0 1"/>
    </joint>


    <link name="wheel_front">
        <inertial>
            <origin xyz="0.0 0 0" rpy="1.57 0 0"/>
            <mass value="0.100"/>
            <inertia ixx="0.0003521" ixy="0" ixz="0" iyy="0.0004586" iyx="0" iyz="0" izz="0.0003521" izx="0" izy="0"/>
        </inertial>

        <visual>
            <origin xyz="0.0 0 0" rpy="1.57 0 0"/>
            <geometry>
                <cylinder length="0.01" radius="0.032"/>
            </geometry>
            <material name="Gray">
                <color rgba="0.3 0.3 0.3 1.0"/>
            </material>
        </visual>
        <collision>
            <origin xyz="0.0 0 0" rpy="1.57 0 0"/>

            <geometry>
                <cylinder length="0.01" radius="0.032"/>
            </geometry>
        </collision>
    </link>

    <joint name="wheel_front_to_conn" type="continuous">
        <parent link="front_wheel_conn"/>
        <child link="wheel_front"/>
        <origin xyz="0.02 0 -0.034"/>
        <axis xyz="0 1 0"/>
    </joint>

    <link name="base_scan_link" type="laser">
        <visual>
            <origin rpy="0 0 0" xyz="0 0 0"/>
            <geometry>
                <cylinder radius="0.044" length="0.026"/>
            </geometry>
            <material name="Orange">
                <color rgba="1.0 0.5 0.0 1.0"/>
            </material>
        </visual>
    </link>


    <!--LASER JOINTS-->
    <joint name="base_laser_base" type="fixed">
        <parent link="base_link"/>
        <child link="base_scan_link"/>
        <origin xyz="0.436 0 0.105" rpy="0 0 0"/>
    </joint>


    <link name="zed_left_camera">
        <visual>
            <origin xyz="0 0 0" rpy="0 1.57 0"/>
            <geometry>
                <cylinder radius="0.007" length=".031"/>
            </geometry>
            <material name="dark_grey">
                <color rgba="0.1 0.1 0.1 1"/>
            </material>
        </visual>
    </link>
    <link name="zed_center">
        <visual>
            <origin xyz="0 0 0" rpy="0 0 0"/>
            <geometry>
                <box size="0.01 0.01 0.01"/>
            </geometry>
            <material name="light_grey">
                <color rgba="0.8 0.8 0.8 0.8"/>
            </material>
        </visual>
    </link>
    <link name="zed_right_camera">
        <visual>
            <origin xyz="0 0 0" rpy="0 1.57 0"/>
            <geometry>
                <cylinder radius="0.007" length=".031"/>
            </geometry>
            <material name="dark_grey">
                <color rgba="0.1 0.1 0.1 1"/>
            </material>
        </visual>
    </link>
    <link name="zed_depth_camera" />

    <joint name="zed_left_camera_joint" type="fixed">
        <parent link="zed_center"/>
        <child link="zed_left_camera"/>
        <origin xyz="0 0.06 0" rpy="0 0 0" />
    </joint>
    <joint name="zed_depth_camera_joint" type="fixed">
        <parent link="zed_left_camera"/>
        <child link="zed_depth_camera"/>
        <origin xyz="0 0 0" rpy="-1.5707963267948966 0 -1.5707963267948966" />
    </joint>

    <joint name="zed_right_camera_joint" type="fixed">
        <parent link="zed_center"/>
        <child link="zed_right_camera"/>
        <origin xyz="0 -0.06 0" rpy="0 0 0" />
    </joint>

    <joint name="zed_camera_to_base_link" type="fixed">
        <origin xyz="0.15 0 1.135" rpy="0 0.3839 0" />
        <parent link="base_link" />
        <child link="zed_center" />
    </joint>

    <link name="imu_link">
        <visual>
            <origin rpy="0 0 0" xyz="0 0 0"/>
            <geometry>
                <box size="0.0275 0.04 0.001"/>
            </geometry>
        </visual>

        <collision>
            <origin rpy="0 0 0" xyz="0 0 0.41"/>
            <geometry>
                <box size=".001 .001 .001"/>
            </geometry>
        </collision>
    </link>

    <joint name="imu_joint" type="fixed">
        <origin xyz="0 0 0.41"/>
        <parent link="base_link"/>
        <child link="imu_link"/>
    </joint>

    <link name="gps_link">
        <visual>
        <origin xyz="0.1 0.1 0" rpy="0 0 0"/>
        <geometry>
            <box size="0.01 0.01 0.01"/>
        </geometry>
        </visual>
    <collision>
    <origin xyz="0.1 0.1 0" rpy="0 0 0"/>
        <geometry>
            <box size="0.01 0.01 0.01"/>
        </geometry>
        </collision>
    </link>

    <joint name="gps_joint" type="fixed">
        <axis xyz="1 0 0"/>
        <origin xyz="0.1 0.1 0"/>
        <parent link="base_link"/>
        <child link="gps_link"/>
    </joint>

    <link name="ultrasonic_link">
        <visual>
            <origin xyz="0 0 0" rpy="0 0 0"/>
        <geometry>
                <box size="0.01 0.01 0.01"/>
            </geometry>
        </visual>

        <collision>
            <origin xyz="0 0 0" rpy="0 0 0"/>
            <geometry>
                <box size="0.01 0.01 0.01"/>
            </geometry>
        </collision>
    </link>

    <joint name="ultrasonic_base_joint" type="fixed">
        <parent link="base_link"/>
        <child link="ultrasonic_link"/>
        <origin xyz="-0.41 0 0.105" rpy="0 0 3.14"/>
    </joint>



<!-- Gazebo Plugins -->

    <gazebo>
        <plugin name="differential_drive_controller" filename="libgazebo_ros_diff_drive.so">
            <publishWheelTF>false</publishWheelTF>
            <publishWheelJointState>false</publishWheelJointState>
            <alwaysOn>true</alwaysOn>
            <updateRate>10</updateRate>
            <wheelAcceleration>0</wheelAcceleration>
            <rosDebugLevel>Debug</rosDebugLevel>
            <wheelTorque>12</wheelTorque>

            <leftJoint>base_link_to_left_wheel_back</leftJoint>
            <rightJoint>base_link_to_right_wheel_back</rightJoint>
            <wheelSeparation>0.6</wheelSeparation>
            <wheelDiameter>0.38</wheelDiameter>
            <commandTopic>cmd_vel</commandTopic>
            <odometryFrame>odom</odometryFrame>
            <odometryTopic>odom</odometryTopic>
            <robotBaseFrame>base_link</robotBaseFrame>
            <legacyMode>false</legacyMode>
        </plugin>
    </gazebo>

    <gazebo reference="base_scan_link">
        <sensor type="ray" name="laser">
            <always_on>true</always_on>
            <update_rate>10</update_rate>
            <visualize>true</visualize>
            <ray>
                <scan>
                    <horizontal>
                        <samples>640</samples>
                        <resolution>1</resolution>
                        <min_angle>-2.35</min_angle>
                        <max_angle>2.35</max_angle>
                    </horizontal>
                </scan>
                <range>
                    <min>0.5</min>
                    <max>100.0</max>
                    <resolution>0.5</resolution>
                </range>
                <noise>
                    <type>gaussian</type>
                    <mean>0.0</mean>
                    <stddev>0.01</stddev>
                </noise>
            </ray>
            <plugin name="gazebo_ros_base_scan_link_controller" filename="libgazebo_ros_laser.so">
                <topicName>/scan</topicName>
                <frameName>base_scan_link</frameName>
                <robotBaseFrame>base_link</robotBaseFrame>
            </plugin>
        </sensor>
    </gazebo>
    

    <gazebo reference="ultrasonic_link">
        <sensor type="ray" name="sonar">
          <pose>0 0 0 0 0 0</pose>
          <update_rate>5</update_rate>
          <ray>
            <scan>
              <horizontal>
                <samples>5</samples>
                <resolution>1.0</resolution>
                <min_angle>-0.25</min_angle>
                <max_angle>0.25</max_angle>
              </horizontal>
              <vertical>
                <samples>5</samples>
                <resolution>1</resolution>
                <min_angle>-0.25</min_angle>
                <max_angle>0.25</max_angle>
              </vertical>
            </scan>
            <range>
              <min>0.01</min>
              <max>0.75</max>
              <resolution>0.01</resolution>
            </range>
          </ray>
          <plugin filename="libgazebo_ros_range.so" name="gazebo_ros_range">
            <gaussianNoise>0.005</gaussianNoise>
            <alwaysOn>true</alwaysOn>
            <updateRate>5</updateRate>
            <topicName>ultrasonic</topicName>
            <frameName>ultrasonic_link</frameName>
            <fov>0.5</fov>
            <radiation>ultrasound</radiation>
          </plugin>
        </sensor>
    </gazebo>

    <gazebo reference="zed_left_camera">
        <sensor type="depth" name="stereocamera">
            <always_on>1</always_on>
            <visualize>true</visualize>
            <camera>
                <horizontal_fov>1.92</horizontal_fov>
                <image>
                    <width>2560</width>
                    <height>720</height>
                    <format>R8G8B8</format>
                </image>
                <depth_camera>
                </depth_camera>
                <clip>
                    <near>0.5</near>
                    <far>20</far>
                </clip>
                <noise>
                    <type>gaussian</type>
                    <mean>0.0</mean>
                    <stddev>0.05</stddev>
                </noise>
            </camera>
            <plugin name="camera_controller" filename="libgazebo_ros_depth_camera.so">
                <alwaysOn>true</alwaysOn>
                <updateRate>10.0</updateRate>
                <cameraName>zed</cameraName>
                <frameName>zed_depth_camera</frameName>
                <imageTopicName>rgb/image_raw</imageTopicName>
                <depthImageTopicName>depth/image_raw</depthImageTopicName>
                <pointCloudTopicName>depth/points</pointCloudTopicName>
                <cameraInfoTopicName>rgb/camera_info</cameraInfoTopicName>
                <depthImageCameraInfoTopicName>depth/camera_info</depthImageCameraInfoTopicName>
                <pointCloudCutoff>0.5</pointCloudCutoff>
                <hackBaseline>0.07</hackBaseline>
                <distortionK1>0.00001</distortionK1>
                <distortionK2>0.00001</distortionK2>
                <distortionK3>0.00001</distortionK3>
                <distortionT1>0.00001</distortionT1>
                <distortionT2>0.00001</distortionT2>
                <CxPrime>0.0</CxPrime>
                <Cx>360</Cx>
                <Cy>240</Cy>
                <focalLength>0.0</focalLength>
                <hackBaseline>0</hackBaseline>
            </plugin>
        </sensor>
    </gazebo>

    <gazebo>
        <plugin name="imu_controller" filename="libgazebo_ros_imu.so">
            <alwaysOn>true</alwaysOn>
            <updateRate>25.0</updateRate>
            <bodyName>imu_link</bodyName>
            <topicName>imu</topicName>
            <serviceName>imu</serviceName>
            <frameName>imu</frameName>
            <gaussianNoise>0.0</gaussianNoise>
            <xyzOffsets>0 0 0</xyzOffsets>
            <rpyOffsets>0 0 0</rpyOffsets>
        </plugin>
    </gazebo>

    <gazebo>
    <plugin name="gps_controller" filename="libhector_gazebo_ros_gps.so">
    <updateRate>50.0</updateRate>
    <bodyName>base_link</bodyName>
    <alwaysOn>true</alwaysOn>
    <topicName>gps</topicName>
    <serviceName>gps_service</serviceName>
    <velocityTopicName>gps_velocity</velocityTopicName>
    <drift>0.0 0.0 0.0</drift>
    <gaussianNoise>0.0 0.0 0.0</gaussianNoise>
    <velocityDrift>0 0 0</velocityDrift>
    <velocityGaussianNoise>0.0 0.0 0.0</velocityGaussianNoise>
    </plugin>
    </gazebo>


</robot>
